Workbook

Sheet Start here
A1: Startup idea research | B1: Which pre-seed ideas are incubators funding, and where can two founders from India apply?
A3: How to read this file
A4: Themes overview | B4: All themes on one page with how many companies YC funded in each of its last 5 batches. Start here to see what is rising.
A5: Incubators | B5: Each program: money, equity taken, who can apply, timing, and how far to trust the row.
A6: One tab per theme | B6: Each theme tab lists funded startups with the idea in one plain sentence. Rows based in India are shaded yellow.
A7: India-based | B7: Every funded startup in this file that is based in India, across all themes.
A8: YC all 900 | B8: Every YC company from Fall 2025 to Fall 2026 with YC's own one-line description and its theme. Use the filters.
A10: What the columns mean
A11: Funding | B11: The program's standard cheque unless the startup's own round was reported. The next column says which.
A12: India / USA / Other | B12: Where the company is based, not where the founders are from. 'Unknown' means the source did not say.
A13: Indian founders? | B13: yes = source says so or company is in India. reported = a newsletter lists them as Indian-origin, not verified. unknown = not checked.
A14: Confidence | B14: high = official directory or the program's own page. medium = news report. low = third-party list.
A16: Where the data lives | B16: This file is generated from the CSV files in data/ by scripts/build_workbook.py. Edit the CSVs, not this file.
A17: Research date | B17: 2026-10-13

Sheet Themes overview
A1: Theme | B1: What it means in simple words | C1: Tab name | D1: Startups listed in this file | E1: YC Fall 2025 | F1: YC Winter 2026 | G1: YC Spring 2026 | H1: YC Summer 2026 | I1: YC Fall 2026 | J1: YC total (5 batches) | K1: Share of Fall 2025 batch | L1: Share of Summer 2026 batch
A2: AI-native service companies | B2: Instead of selling software to a law firm or an accounting firm, the startup IS the firm. It sells the finished work (a filed tax return, an insurance policy, a collected debt) and uses AI internally so it needs far fewer people. | C2: AI service firms | D2: =COUNTA('AI service firms'!$B:$B)-1 -> 18 | E2: =COUNTIFS('YC all 900'!$A:$A,$C2,'YC all 900'!$E:$E,"Fall 2025") -> 4 | F2: =COUNTIFS('YC all 900'!$A:$A,$C2,'YC all 900'!$E:$E,"Winter 2026") -> 8 | G2: =COUNTIFS('YC all 900'!$A:$A,$C2,'YC all 900'!$E:$E,"Spring 2026") -> 9 | H2: =COUNTIFS('YC all 900'!$A:$A,$C2,'YC all 900'!$E:$E,"Summer 2026") -> 20 | I2: =COUNTIFS('YC all 900'!$A:$A,$C2,'YC all 900'!$E:$E,"Fall 2026") -> 6 | J2: =SUM(E2:I2) -> 47 | K2: =IF(E$25=0,0,E2/E$25) -> 0.027586207 | L2: =IF(H$25=0,0,H2/H$25) -> 0.086956522
A3: AI for traditional industries | B3: An "AI employee" or "AI operating system" for one old-school industry: hotels, restaurants, auto repair shops, construction, trucking, wholesale distributors, property managers. | C3: Old-industry AI | D3: =COUNTA('Old-industry AI'!$B:$B)-1 -> 21 | E3: =COUNTIFS('YC all 900'!$A:$A,$C3,'YC all 900'!$E:$E,"Fall 2025") -> 10 | F3: =COUNTIFS('YC all 900'!$A:$A,$C3,'YC all 900'!$E:$E,"Winter 2026") -> 13 | G3: =COUNTIFS('YC all 900'!$A:$A,$C3,'YC all 900'!$E:$E,"Spring 2026") -> 11 | H3: =COUNTIFS('YC all 900'!$A:$A,$C3,'YC all 900'!$E:$E,"Summer 2026") -> 13 | I3: =COUNTIFS('YC all 900'!$A:$A,$C3,'YC all 900'!$E:$E,"Fall 2026") -> 3 | J3: =SUM(E3:I3) -> 50 | K3: =IF(E$25=0,0,E3/E$25) -> 0.068965517 | L3: =IF(H$25=0,0,H3/H$25) -> 0.056521739
A4: AI for finance and back-office teams | B4: AI agents that do the boring finance work inside companies, banks, lenders and insurers: bookkeeping, invoices, audits, loan files, claims, compliance checks, investment research. | C4: Finance back-office | D4: =COUNTA('Finance back-office'!$B:$B)-1 -> 18 | E4: =COUNTIFS('YC all 900'!$A:$A,$C4,'YC all 900'!$E:$E,"Fall 2025") -> 8 | F4: =COUNTIFS('YC all 900'!$A:$A,$C4,'YC all 900'!$E:$E,"Winter 2026") -> 12 | G4: =COUNTIFS('YC all 900'!$A:$A,$C4,'YC all 900'!$E:$E,"Spring 2026") -> 6 | H4: =COUNTIFS('YC all 900'!$A:$A,$C4,'YC all 900'!$E:$E,"Summer 2026") -> 5 | I4: =COUNTIFS('YC all 900'!$A:$A,$C4,'YC all 900'!$E:$E,"Fall 2026") -> 9 | J4: =SUM(E4:I4) -> 40 | K4: =IF(E$25=0,0,E4/E$25) -> 0.055172414 | L4: =IF(H$25=0,0,H4/H$25) -> 0.02173913
A5: Healthcare AI | B5: AI for clinics, hospitals and patients: medical billing, insurance approvals, front-desk calls, AI doctors and health assistants, medical imaging. | C5: Healthcare AI | D5: =COUNTA('Healthcare AI'!$B:$B)-1 -> 26 | E5: =COUNTIFS('YC all 900'!$A:$A,$C5,'YC all 900'!$E:$E,"Fall 2025") -> 8 | F5: =COUNTIFS('YC all 900'!$A:$A,$C5,'YC all 900'!$E:$E,"Winter 2026") -> 11 | G5: =COUNTIFS('YC all 900'!$A:$A,$C5,'YC all 900'!$E:$E,"Spring 2026") -> 10 | H5: =COUNTIFS('YC all 900'!$A:$A,$C5,'YC all 900'!$E:$E,"Summer 2026") -> 8 | I5: =COUNTIFS('YC all 900'!$A:$A,$C5,'YC all 900'!$E:$E,"Fall 2026") -> 6 | J5: =SUM(E5:I5) -> 43 | K5: =IF(E$25=0,0,E5/E$25) -> 0.055172414 | L5: =IF(H$25=0,0,H5/H$25) -> 0.034782609
A6: Enterprise AI workers and company brain | B6: General-purpose AI employees for any company, a "company brain" that remembers everything the company knows, customer-support agents, and teams that go into a big company and automate its work for it. | C6: AI workforce | D6: =COUNTA('AI workforce'!$B:$B)-1 -> 20 | E6: =COUNTIFS('YC all 900'!$A:$A,$C6,'YC all 900'!$E:$E,"Fall 2025") -> 12 | F6: =COUNTIFS('YC all 900'!$A:$A,$C6,'YC all 900'!$E:$E,"Winter 2026") -> 9 | G6: =COUNTIFS('YC all 900'!$A:$A,$C6,'YC all 900'!$E:$E,"Spring 2026") -> 17 | H6: =COUNTIFS('YC all 900'!$A:$A,$C6,'YC all 900'!$E:$E,"Summer 2026") -> 14 | I6: =COUNTIFS('YC all 900'!$A:$A,$C6,'YC all 900'!$E:$E,"Fall 2026") -> 5 | J6: =SUM(E6:I6) -> 57 | K6: =IF(E$25=0,0,E6/E$25) -> 0.082758621 | L6: =IF(H$25=0,0,H6/H$25) -> 0.060869565
A7: Sales, marketing and growth AI | B7: AI that finds customers, runs ads, writes marketing content, coaches sales calls, and helps a product get recommended by ChatGPT-style assistants. | C7: Sales and marketing | D7: =COUNTA('Sales and marketing'!$B:$B)-1 -> 20 | E7: =COUNTIFS('YC all 900'!$A:$A,$C7,'YC all 900'!$E:$E,"Fall 2025") -> 11 | F7: =COUNTIFS('YC all 900'!$A:$A,$C7,'YC all 900'!$E:$E,"Winter 2026") -> 12 | G7: =COUNTIFS('YC all 900'!$A:$A,$C7,'YC all 900'!$E:$E,"Spring 2026") -> 18 | H7: =COUNTIFS('YC all 900'!$A:$A,$C7,'YC all 900'!$E:$E,"Summer 2026") -> 8 | I7: =COUNTIFS('YC all 900'!$A:$A,$C7,'YC all 900'!$E:$E,"Fall 2026") -> 5 | J7: =SUM(E7:I7) -> 54 | K7: =IF(E$25=0,0,E7/E$25) -> 0.075862069 | L7: =IF(H$25=0,0,H7/H$25) -> 0.034782609
A8: Recruiting and hiring | B8: AI recruiters, hiring marketplaces, tools that test candidates, and agents that apply to jobs for you. | C8: Hiring | D8: =COUNTA(Hiring!$B:$B)-1 -> 8 | E8: =COUNTIFS('YC all 900'!$A:$A,$C8,'YC all 900'!$E:$E,"Fall 2025") -> 1 | F8: =COUNTIFS('YC all 900'!$A:$A,$C8,'YC all 900'!$E:$E,"Winter 2026") -> 2 | G8: =COUNTIFS('YC all 900'!$A:$A,$C8,'YC all 900'!$E:$E,"Spring 2026") -> 5 | H8: =COUNTIFS('YC all 900'!$A:$A,$C8,'YC all 900'!$E:$E,"Summer 2026") -> 2 | I8: =COUNTIFS('YC all 900'!$A:$A,$C8,'YC all 900'!$E:$E,"Fall 2026") -> 1 | J8: =SUM(E8:I8) -> 11 | K8: =IF(E$25=0,0,E8/E$25) -> 0.0068965517 | L8: =IF(H$25=0,0,H8/H$25) -> 0.0086956522
A9: Legal, compliance and government | B9: Software (not a law firm) for lawyers, compliance teams, patent work, product certifications, and government offices. | C9: Legal and gov | D9: =COUNTA('Legal and gov'!$B:$B)-1 -> 13 | E9: =COUNTIFS('YC all 900'!$A:$A,$C9,'YC all 900'!$E:$E,"Fall 2025") -> 6 | F9: =COUNTIFS('YC all 900'!$A:$A,$C9,'YC all 900'!$E:$E,"Winter 2026") -> 5 | G9: =COUNTIFS('YC all 900'!$A:$A,$C9,'YC all 900'!$E:$E,"Spring 2026") -> 5 | H9: =COUNTIFS('YC all 900'!$A:$A,$C9,'YC all 900'!$E:$E,"Summer 2026") -> 5 | I9: =COUNTIFS('YC all 900'!$A:$A,$C9,'YC all 900'!$E:$E,"Fall 2026") -> 3 | J9: =SUM(E9:I9) -> 24 | K9: =IF(E$25=0,0,E9/E$25) -> 0.04137931 | L9: =IF(H$25=0,0,H9/H$25) -> 0.02173913
A10: Infrastructure for AI agents | B10: The plumbing AI agents need to work on their own: a computer to run on, a wallet to pay with, a phone number, an identity, memory, web access, and cheaper model usage. | C10: Agent infrastructure | D10: =COUNTA('Agent infrastructure'!$B:$B)-1 -> 19 | E10: =COUNTIFS('YC all 900'!$A:$A,$C10,'YC all 900'!$E:$E,"Fall 2025") -> 7 | F10: =COUNTIFS('YC all 900'!$A:$A,$C10,'YC all 900'!$E:$E,"Winter 2026") -> 13 | G10: =COUNTIFS('YC all 900'!$A:$A,$C10,'YC all 900'!$E:$E,"Spring 2026") -> 9 | H10: =COUNTIFS('YC all 900'!$A:$A,$C10,'YC all 900'!$E:$E,"Summer 2026") -> 14 | I10: =COUNTIFS('YC all 900'!$A:$A,$C10,'YC all 900'!$E:$E,"Fall 2026") -> 12 | J10: =SUM(E10:I10) -> 55 | K10: =IF(E$25=0,0,E10/E$25) -> 0.048275862 | L10: =IF(H$25=0,0,H10/H$25) -> 0.060869565
A11: Agent reliability, testing and security | B11: Tools that check whether AI agents work correctly and safely: monitoring, testing in fake environments, guardrails, permission control, plus classic cybersecurity done by AI. | C11: Agent safety | D11: =COUNTA('Agent safety'!$B:$B)-1 -> 22 | E11: =COUNTIFS('YC all 900'!$A:$A,$C11,'YC all 900'!$E:$E,"Fall 2025") -> 6 | F11: =COUNTIFS('YC all 900'!$A:$A,$C11,'YC all 900'!$E:$E,"Winter 2026") -> 15 | G11: =COUNTIFS('YC all 900'!$A:$A,$C11,'YC all 900'!$E:$E,"Spring 2026") -> 9 | H11: =COUNTIFS('YC all 900'!$A:$A,$C11,'YC all 900'!$E:$E,"Summer 2026") -> 9 | I11: =COUNTIFS('YC all 900'!$A:$A,$C11,'YC all 900'!$E:$E,"Fall 2026") -> 11 | J11: =SUM(E11:I11) -> 50 | K11: =IF(E$25=0,0,E11/E$25) -> 0.04137931 | L11: =IF(H$25=0,0,H11/H$25) -> 0.039130435
A12: Coding agents and developer tools | B12: AI that writes, reviews, tests and operates software, and the tools around it: new code hosting, cloud dev machines, on-call agents that fix outages. | C12: Coding and dev tools | D12: =COUNTA('Coding and dev tools'!$B:$B)-1 -> 17 | E12: =COUNTIFS('YC all 900'!$A:$A,$C12,'YC all 900'!$E:$E,"Fall 2025") -> 14 | F12: =COUNTIFS('YC all 900'!$A:$A,$C12,'YC all 900'!$E:$E,"Winter 2026") -> 14 | G12: =COUNTIFS('YC all 900'!$A:$A,$C12,'YC all 900'!$E:$E,"Spring 2026") -> 16 | H12: =COUNTIFS('YC all 900'!$A:$A,$C12,'YC all 900'!$E:$E,"Summer 2026") -> 10 | I12: =COUNTIFS('YC all 900'!$A:$A,$C12,'YC all 900'!$E:$E,"Fall 2026") -> 7 | J12: =SUM(E12:I12) -> 61 | K12: =IF(E$25=0,0,E12/E$25) -> 0.096551724 | L12: =IF(H$25=0,0,H12/H$25) -> 0.043478261
A13: Training data and practice environments for AI | B13: Companies that sell data to AI labs: expert-written answers, recordings of people doing computer work, robot and human-movement data, practice "gyms" and benchmarks for models. | C13: Training data | D13: =COUNTA('Training data'!$B:$B)-1 -> 12 | E13: =COUNTIFS('YC all 900'!$A:$A,$C13,'YC all 900'!$E:$E,"Fall 2025") -> 5 | F13: =COUNTIFS('YC all 900'!$A:$A,$C13,'YC all 900'!$E:$E,"Winter 2026") -> 8 | G13: =COUNTIFS('YC all 900'!$A:$A,$C13,'YC all 900'!$E:$E,"Spring 2026") -> 5 | H13: =COUNTIFS('YC all 900'!$A:$A,$C13,'YC all 900'!$E:$E,"Summer 2026") -> 17 | I13: =COUNTIFS('YC all 900'!$A:$A,$C13,'YC all 900'!$E:$E,"Fall 2026") -> 3 | J13: =SUM(E13:I13) -> 38 | K13: =IF(E$25=0,0,E13/E$25) -> 0.034482759 | L13: =IF(H$25=0,0,H13/H$25) -> 0.073913043
A14: AI models, research labs and compute | B14: New AI models, small research labs, cheaper and faster clouds for running models, and GPU marketplaces. | C14: Models and compute | D14: =COUNTA('Models and compute'!$B:$B)-1 -> 18 | E14: =COUNTIFS('YC all 900'!$A:$A,$C14,'YC all 900'!$E:$E,"Fall 2025") -> 2 | F14: =COUNTIFS('YC all 900'!$A:$A,$C14,'YC all 900'!$E:$E,"Winter 2026") -> 10 | G14: =COUNTIFS('YC all 900'!$A:$A,$C14,'YC all 900'!$E:$E,"Spring 2026") -> 6 | H14: =COUNTIFS('YC all 900'!$A:$A,$C14,'YC all 900'!$E:$E,"Summer 2026") -> 9 | I14: =COUNTIFS('YC all 900'!$A:$A,$C14,'YC all 900'!$E:$E,"Fall 2026") -> 6 | J14: =SUM(E14:I14) -> 33 | K14: =IF(E$25=0,0,E14/E$25) -> 0.013793103 | L14: =IF(H$25=0,0,H14/H$25) -> 0.039130435
A15: Voice AI | B15: AI that talks and listens: voice agents for phone calls, speech models for many languages, voice infrastructure. | C15: Voice AI | D15: =COUNTA('Voice AI'!$B:$B)-1 -> 11 | E15: =COUNTIFS('YC all 900'!$A:$A,$C15,'YC all 900'!$E:$E,"Fall 2025") -> 3 | F15: =COUNTIFS('YC all 900'!$A:$A,$C15,'YC all 900'!$E:$E,"Winter 2026") -> 2 | G15: =COUNTIFS('YC all 900'!$A:$A,$C15,'YC all 900'!$E:$E,"Spring 2026") -> 3 | H15: =COUNTIFS('YC all 900'!$A:$A,$C15,'YC all 900'!$E:$E,"Summer 2026") -> 1 | I15: =COUNTIFS('YC all 900'!$A:$A,$C15,'YC all 900'!$E:$E,"Fall 2026") -> 1 | J15: =SUM(E15:I15) -> 10 | K15: =IF(E$25=0,0,E15/E$25) -> 0.020689655 | L15: =IF(H$25=0,0,H15/H$25) -> 0.0043478261
A16: Robotics and physical AI | B16: Humanoids, warehouse and farm robots, robot parts, and software that lets robots learn and be deployed. | C16: Robotics | D16: =COUNTA(Robotics!$B:$B)-1 -> 17 | E16: =COUNTIFS('YC all 900'!$A:$A,$C16,'YC all 900'!$E:$E,"Fall 2025") -> 6 | F16: =COUNTIFS('YC all 900'!$A:$A,$C16,'YC all 900'!$E:$E,"Winter 2026") -> 8 | G16: =COUNTIFS('YC all 900'!$A:$A,$C16,'YC all 900'!$E:$E,"Spring 2026") -> 9 | H16: =COUNTIFS('YC all 900'!$A:$A,$C16,'YC all 900'!$E:$E,"Summer 2026") -> 18 | I16: =COUNTIFS('YC all 900'!$A:$A,$C16,'YC all 900'!$E:$E,"Fall 2026") -> 11 | J16: =SUM(E16:I16) -> 52 | K16: =IF(E$25=0,0,E16/E$25) -> 0.04137931 | L16: =IF(H$25=0,0,H16/H$25) -> 0.07826087
A17: Defense, drones, aviation and space | B17: Counter-drone systems, interceptors, military drones, satellites, rockets, aviation software. | C17: Defense and space | D17: =COUNTA('Defense and space'!$B:$B)-1 -> 15 | E17: =COUNTIFS('YC all 900'!$A:$A,$C17,'YC all 900'!$E:$E,"Fall 2025") -> 5 | F17: =COUNTIFS('YC all 900'!$A:$A,$C17,'YC all 900'!$E:$E,"Winter 2026") -> 9 | G17: =COUNTIFS('YC all 900'!$A:$A,$C17,'YC all 900'!$E:$E,"Spring 2026") -> 7 | H17: =COUNTIFS('YC all 900'!$A:$A,$C17,'YC all 900'!$E:$E,"Summer 2026") -> 11 | I17: =COUNTIFS('YC all 900'!$A:$A,$C17,'YC all 900'!$E:$E,"Fall 2026") -> 9 | J17: =SUM(E17:I17) -> 41 | K17: =IF(E$25=0,0,E17/E$25) -> 0.034482759 | L17: =IF(H$25=0,0,H17/H$25) -> 0.047826087
A18: Manufacturing, hardware, chips and energy | B18: Factories and factory software, chip design and chip making, design tools for hardware engineers, data-center power and cooling, nuclear and grid. | C18: Industrial and hardware | D18: =COUNTA('Industrial and hardware'!$B:$B)-1 -> 28 | E18: =COUNTIFS('YC all 900'!$A:$A,$C18,'YC all 900'!$E:$E,"Fall 2025") -> 3 | F18: =COUNTIFS('YC all 900'!$A:$A,$C18,'YC all 900'!$E:$E,"Winter 2026") -> 10 | G18: =COUNTIFS('YC all 900'!$A:$A,$C18,'YC all 900'!$E:$E,"Spring 2026") -> 11 | H18: =COUNTIFS('YC all 900'!$A:$A,$C18,'YC all 900'!$E:$E,"Summer 2026") -> 30 | I18: =COUNTIFS('YC all 900'!$A:$A,$C18,'YC all 900'!$E:$E,"Fall 2026") -> 15 | J18: =SUM(E18:I18) -> 69 | K18: =IF(E$25=0,0,E18/E$25) -> 0.020689655 | L18: =IF(H$25=0,0,H18/H$25) -> 0.13043478
A19: Fintech, trading and markets | B19: Prediction-market tools, trading apps, AI hedge funds, stablecoin payments, insurance for AI risks, cross-border payments. | C19: Fintech and markets | D19: =COUNTA('Fintech and markets'!$B:$B)-1 -> 20 | E19: =COUNTIFS('YC all 900'!$A:$A,$C19,'YC all 900'!$E:$E,"Fall 2025") -> 7 | F19: =COUNTIFS('YC all 900'!$A:$A,$C19,'YC all 900'!$E:$E,"Winter 2026") -> 11 | G19: =COUNTIFS('YC all 900'!$A:$A,$C19,'YC all 900'!$E:$E,"Spring 2026") -> 13 | H19: =COUNTIFS('YC all 900'!$A:$A,$C19,'YC all 900'!$E:$E,"Summer 2026") -> 15 | I19: =COUNTIFS('YC all 900'!$A:$A,$C19,'YC all 900'!$E:$E,"Fall 2026") -> 2 | J19: =SUM(E19:I19) -> 48 | K19: =IF(E$25=0,0,E19/E$25) -> 0.048275862 | L19: =IF(H$25=0,0,H19/H$25) -> 0.065217391
A20: Biotech, drug discovery and AI for science | B20: AI scientists, drug discovery, lab automation, new materials, regulatory paperwork for life sciences. | C20: Bio and science | D20: =COUNTA('Bio and science'!$B:$B)-1 -> 10 | E20: =COUNTIFS('YC all 900'!$A:$A,$C20,'YC all 900'!$E:$E,"Fall 2025") -> 5 | F20: =COUNTIFS('YC all 900'!$A:$A,$C20,'YC all 900'!$E:$E,"Winter 2026") -> 9 | G20: =COUNTIFS('YC all 900'!$A:$A,$C20,'YC all 900'!$E:$E,"Spring 2026") -> 7 | H20: =COUNTIFS('YC all 900'!$A:$A,$C20,'YC all 900'!$E:$E,"Summer 2026") -> 9 | I20: =COUNTIFS('YC all 900'!$A:$A,$C20,'YC all 900'!$E:$E,"Fall 2026") -> 6 | J20: =SUM(E20:I20) -> 36 | K20: =IF(E$25=0,0,E20/E$25) -> 0.034482759 | L20: =IF(H$25=0,0,H20/H$25) -> 0.039130435
A21: Consumer apps and consumer hardware | B21: Apps and gadgets for normal people: learning, games, health coaching, social, shopping, wearables. | C21: Consumer apps | D21: =COUNTA('Consumer apps'!$B:$B)-1 -> 19 | E21: =COUNTIFS('YC all 900'!$A:$A,$C21,'YC all 900'!$E:$E,"Fall 2025") -> 11 | F21: =COUNTIFS('YC all 900'!$A:$A,$C21,'YC all 900'!$E:$E,"Winter 2026") -> 8 | G21: =COUNTIFS('YC all 900'!$A:$A,$C21,'YC all 900'!$E:$E,"Spring 2026") -> 8 | H21: =COUNTIFS('YC all 900'!$A:$A,$C21,'YC all 900'!$E:$E,"Summer 2026") -> 7 | I21: =COUNTIFS('YC all 900'!$A:$A,$C21,'YC all 900'!$E:$E,"Fall 2026") -> 4 | J21: =SUM(E21:I21) -> 38 | K21: =IF(E$25=0,0,E21/E$25) -> 0.075862069 | L21: =IF(H$25=0,0,H21/H$25) -> 0.030434783
A22: Personal AI assistants and AI devices | B22: An AI assistant that does your own work and errands, AI-first browsers and desktops, and new devices (earbuds, glasses, pins, phones) built around AI. | C22: Personal AI | D22: =COUNTA('Personal AI'!$B:$B)-1 -> 12 | E22: =COUNTIFS('YC all 900'!$A:$A,$C22,'YC all 900'!$E:$E,"Fall 2025") -> 3 | F22: =COUNTIFS('YC all 900'!$A:$A,$C22,'YC all 900'!$E:$E,"Winter 2026") -> 5 | G22: =COUNTIFS('YC all 900'!$A:$A,$C22,'YC all 900'!$E:$E,"Spring 2026") -> 7 | H22: =COUNTIFS('YC all 900'!$A:$A,$C22,'YC all 900'!$E:$E,"Summer 2026") -> 3 | I22: =COUNTIFS('YC all 900'!$A:$A,$C22,'YC all 900'!$E:$E,"Fall 2026") -> 7 | J22: =SUM(E22:I22) -> 25 | K22: =IF(E$25=0,0,E22/E$25) -> 0.020689655 | L22: =IF(H$25=0,0,H22/H$25) -> 0.013043478
A23: Creative and media tools | B23: AI video editors, AI film making, design tools, avatars. | C23: Creative tools | D23: =COUNTA('Creative tools'!$B:$B)-1 -> 10 | E23: =COUNTIFS('YC all 900'!$A:$A,$C23,'YC all 900'!$E:$E,"Fall 2025") -> 7 | F23: =COUNTIFS('YC all 900'!$A:$A,$C23,'YC all 900'!$E:$E,"Winter 2026") -> 3 | G23: =COUNTIFS('YC all 900'!$A:$A,$C23,'YC all 900'!$E:$E,"Spring 2026") -> 1 | H23: =COUNTIFS('YC all 900'!$A:$A,$C23,'YC all 900'!$E:$E,"Summer 2026") -> 2 | I23: =COUNTIFS('YC all 900'!$A:$A,$C23,'YC all 900'!$E:$E,"Fall 2026") -> 2 | J23: =SUM(E23:I23) -> 15 | K23: =IF(E$25=0,0,E23/E$25) -> 0.048275862 | L23: =IF(H$25=0,0,H23/H$25) -> 0.0086956522
A24: Other or unclear | B24: Companies with no public description yet. | C24: Other | D24: =COUNTA(Other!$B:$B)-1 -> 0 | E24: =COUNTIFS('YC all 900'!$A:$A,$C24,'YC all 900'!$E:$E,"Fall 2025") -> 1 | F24: =COUNTIFS('YC all 900'!$A:$A,$C24,'YC all 900'!$E:$E,"Winter 2026") -> 1 | G24: =COUNTIFS('YC all 900'!$A:$A,$C24,'YC all 900'!$E:$E,"Spring 2026") -> 1 | H24: =COUNTIFS('YC all 900'!$A:$A,$C24,'YC all 900'!$E:$E,"Summer 2026") -> 0 | I24: =COUNTIFS('YC all 900'!$A:$A,$C24,'YC all 900'!$E:$E,"Fall 2026") -> 0 | J24: =SUM(E24:I24) -> 3 | K24: =IF(E$25=0,0,E24/E$25) -> 0.0068965517 | L24: =IF(H$25=0,0,H24/H$25) -> 0
A25: Total | D25: =SUM(D2:D24) -> 374 | E25: =SUM(E2:E24) -> 145 | F25: =SUM(F2:F24) -> 198 | G25: =SUM(G2:G24) -> 193 | H25: =SUM(H2:H24) -> 230 | I25: =SUM(I2:I24) -> 134 | J25: =SUM(J2:J24) -> 900
A27: YC counts are formulas over the 'YC all 900' tab (source: yc-oss.github.io/api, read 2026-10-13). Themes were assigned by hand from each company's description; see data/yc_bracket_assignments.csv.

Sheet Incubators
A1: Program | B1: Type | C1: Based in | D1: Can founders in India apply? | E1: Money | F1: Equity taken | G1: Stage and who they want | H1: Format | I1: Student friendly? | J1: Timing / next date | K1: Notes | L1: Source | M1: Confidence
A2: Y Combinator | B2: Accelerator | C2: San Francisco, USA | D2: Yes. Any country can apply. If accepted, the company needs a parent company in the US, Canada, Singapore or Cayman Islands. | E2: $500K | F2: 7% for the first $125K; the other $375K is an uncapped SAFE that converts at the terms of your next round | G2: Any stage, idea to revenue. Wants a founding team and an idea. Non-technical teams need a technical co-founder. | H2: 3 months in person in San Francisco. Four batches a year (Winter, Spring, Summer, Fall). | I2: Yes. Students can apply and can ask to join a batch after they graduate (Early Decision). Founders must work full-time during the batch. | J2: Winter 2027 deadline reported as 2026-11-02, 8pm PT, decisions by 2026-12-11. Confirm on ycombinator.com/apply. | K2: Only 9 of the last 900 YC companies are based in India, while a community estimate says about 20% of Summer 2026 founders are of Indian origin. Most Indian founders in YC run US-based companies. | L2: https://www.ycombinator.com/deal ; https://www.ycombinator.com/faq | M2: high
A3: a16z Speedrun | B3: Accelerator | C3: San Francisco, USA | D3: Not stated in the sources read. The program is in person in San Francisco. | E3: Up to $1M | F3: 10% for the first $500K; a further $500K goes into your next round within 18 months | G3: Pre-seed. Very selective, under 1% accepted (one source: 19,000 applicants for SR006). | H3: About 11 weeks in San Francisco. Two cohorts a year, roughly 50 to 80 startups each. | I3: Not stated. | J3: SR008 runs late January to April 2027. Application dates not found yet. | K3: No board seat. Money is wired on acceptance. Over $5M in partner credits. | L3: https://foundedceo.substack.com/p/a16z-speedruns-sr007-demo-day-is ; https://www.frontrun.vc/blog/a16z-speedrun-cohort-007-companies/ | M3: medium
A4: South Park Commons Founder Fellowship | B4: Fellowship | C4: San Francisco, New York and Bengaluru | D4: Yes. Bengaluru is one of the three bootcamp locations. | E4: Up to $1M | F4: 7% for $400K up front; a further $600K is guaranteed in your next outside-led round | G4: Very early. You do not need an idea to apply. Strong preference for people who can build the product themselves. | H4: 8-week in-person bootcamp. No demo day. | I4: Not stated. | J4: Fall 2026 applications closed 2026-08-02. Next cycle not announced. | K4: A good fit for "we have skills but are still choosing the idea". The size of the India fund is not confirmed. | L4: https://x.com/southpkcommons/status/2074942309599224190 ; https://www.southparkcommons.com/faq | M4: medium
A5: Antler India | B5: Residency + direct investment | C5: Bengaluru, India | D5: Yes, it is the India program. | E5: Up to ₹4 crore (about $425K-$470K) | F5: 11% | G5: Pre-launch, pre-product or pre-revenue teams working full-time. Focus on AI-first startups. | H5: 3-week AI Residency, first 2 weeks in person in Bengaluru, with a one-time ₹2 lakh expense grant. About half of Antler India's investments happen outside the residency. | I5: Not stated. Requires full-time commitment. | J5: Next residency "to be announced soon" (page read 2026-10-13). | K5: Funding decision in 3 weeks. The page claims 50-75% of residency teams get funded. | L5: https://www.antler.co/india | M5: high
A6: Entrepreneur First | B6: Talent investor | C6: London; cohorts in Bangalore and other cities | D6: Yes, runs a Bangalore cohort. | E6: Not confirmed. A 2026 guide says $250K on the US pathway; older Bangalore reports say about $55K plus a monthly stipend. | F6: US pathway reported as 8% for $125K plus a $125K uncapped SAFE. Bangalore terms not confirmed. | G6: Individuals. You join before you have a co-founder or an idea. | H6: Cohort program in Bangalore. | I6: Not stated. | J6: Bangalore Winter 2027: early deadline was 2026-10-05; start reported as January or February 2027. | K6: EF also took part in the $1M pre-seed of ByteAsk (two IIT Delhi graduates, YC Fall 2026). Check terms on EF's own site. | L6: https://hub.causo.ai/guides/how-to-apply-to-entrepreneur-first-2026 | M6: low
A7: Peak XV Surge | B7: Seed program | C7: India and Southeast Asia | D7: Yes. The cohort mixes India-based companies and companies abroad. | E7: Up to $5M per startup (raised from $3M with Surge 12) | F7: Not disclosed | G7: Seed, larger than pre-seed. Most Surge 12 companies had already raised money. | H7: Cohort program. Surge 12 had 18 startups. | I7: Not stated. | J7: Surge 12 was announced 2026-09-28/29. | K7: Peak XV says it put over $50M into Surge 12. Better as a second step than a first cheque. | L7: https://inc42.com/buzz/meet-the-startups-from-peak-xvs-surge-12/ | M7: medium
A8: Accel Atoms (AI Cohort, with Google AI Futures Fund) | B8: Pre-seed program | C8: India | D8: Yes. Built for Indian and Indian-origin founders building AI startups anywhere. | E8: Up to $2M co-investment plus up to $350K compute credits | F8: Not disclosed | G8: Pre-seed AI-first startups. | H8: 3 months, starts in Bengaluru, ends with a visit to Mountain View. | I8: Not stated. | J8: 2026 cohort ran March to June 2026. 5 startups chosen from 4,000+ applicants. Applications currently closed. | K8: Sources disagree on whether $2M is per investor or total. About 0.1% acceptance. | L8: https://www.outlookbusiness.com/deeptech/five-startups-to-join-accel-atoms-and-googles-ai-futures-fund-ai-cohort-2026 | M8: medium
A9: 100X.VC | B9: Pre-seed fund with classes | C9: Mumbai, India | D9: Yes. | E9: ₹1.25 crore | F9: 15% through an iSAFE note | G9: Early-stage Indian startups. | H9: Two classes a year, about 15-22 startups each, ending in a pitch day. | I9: Not stated. | J9: Latest class found: Class 12, early 2025 (18 startups, $2.7M). No 2026 class found yet. | K9: The ₹1.25 crore for 15% terms are from 2022-2023 reports. Confirm on 100x.vc. | L9: https://yourstory.com/2025/01/100xvc-invests-27m-18-startups-12th-cohort | M9: medium
A10: AJVC | B10: Pre-seed fund | C10: India | D10: Yes. | E10: ₹1.5 crore (about $180K) | F10: 9%. The same terms for every startup. | G10: Pre-seed, any sector. | H10: Direct investment, not a cohort. About 12-15 startups a year. | I10: Not stated. | J10: Rolling. | K10: Fixed terms mean no negotiation. Reported to have backed 35+ companies by September 2026. | L10: https://india.entrepreneur.com/news-and-trends/aviral-bhatnagars-ajvc-closes-inr-100-cr-fund-to-back/487821 | M10: medium
A11: All In Capital | B11: Pre-seed and seed fund | C11: Mumbai and Bengaluru, India | D11: Yes. | E11: $100K to $300K | F11: Not disclosed | G11: Pre-seed and seed. | H11: Direct investment. | I11: Not stated. | J11: Rolling. Fund II of ₹200 crore launched. | K11: Fund I put $11M into 51 startups. | L11: https://india.entrepreneur.com/news-and-trends/all-in-capital-launches-inr-200-cr-fund-ii-eyes-inr-300-cr/488785 | M11: medium
A12: Campus Fund | B12: Student-focused VC | C12: India | D12: Yes. | E12: ₹1 crore to ₹8 crore first cheque | F12: Not disclosed | G12: Startups founded by students, recent graduates and dropouts. | H12: Direct investment. "Build In India" sets aside up to $10M for first pre-seed cheques. | I12: Yes. This is the whole point of the fund. | J12: Rolling. Plans 60-80 startups over four years from a $100M fund. | K12: Portfolio leans deep tech, space and climate (Digantara, EtherealX). | L12: https://india.entrepreneur.com/?p=99916 | M12: medium
... A23: FITT, IIT Delhi (with government schemes NIDHI and Startup India Seed Fund) | B23: University incubator | C23: New Delhi, India | D23: Yes. | E23: Not verified. One aggregator shows ₹25 lakh to ₹1 crore for one FITT program. | F23: Not verified | G23: Technology startups, often linked to IIT Delhi. | H23: Incubation at IIT Delhi. | I23: Yes. Akshit can ask FITT directly. | J23: Not found. | K23: Open question: get exact scheme amounts and eligibility from FITT. | L23: https://www.startupgrantsindia.com/providers/fitt-iit-delhi/government-funding-schemes-fitt-implements | M23: low

Sheet AI service firms
A1: Idea in simple words | B1: Startup | C1: Funded by | D1: Batch / cohort | E1: Funding | F1: What the funding number means | G1: Based in | H1: India / USA / Other | I1: Indian founders? | J1: Website | K1: Source | L1: Confidence
A2: A customs broker (the firm that clears imported goods at the border) that runs mostly on AI. | B2: Alchemize | C2: Y Combinator | D2: YC Spring 2026 | E2: $500K | F2: standard YC deal ($125K for 7% + $375K uncapped SAFE); the startup's own round is not public | G2: San Francisco, CA, USA | H2: USA | I2: unknown | J2: https://tryalchemize.com | K2: https://www.ycombinator.com/companies/alchemize | L2: high
A3: A debt collection company where AI, not call-centre staff, contacts people who owe money. | B3: Audun | C3: Y Combinator | D3: YC Summer 2026 | E3: $500K | F3: standard YC deal ($125K for 7% + $375K uncapped SAFE); the startup's own round is not public | G3: Oslo, Oslo, Norway | H3: Other | I3: unknown | J3: https://audun.co | K3: https://www.ycombinator.com/companies/audun | L3: high
A4: An accounting firm that does a client's books with AI and wants to undercut the big accounting firms. | B4: Billow AI Labs | C4: Y Combinator | D4: YC Summer 2026 | E4: $500K | F4: standard YC deal ($125K for 7% + $375K uncapped SAFE); the startup's own round is not public | G4: San Francisco, CA, USA | H4: USA | I4: unknown | J4: https://thebillow.ai/ | K4: https://www.ycombinator.com/companies/billow-ai-labs | L4: high
A5: An insurance broker for businesses where AI does most of the paperwork a human broker would do. | B5: Casey | C5: Y Combinator | D5: YC Fall 2025 | E5: $500K | F5: standard YC deal ($125K for 7% + $375K uncapped SAFE); the startup's own round is not public | G5: San Francisco, CA, USA | H5: USA | I5: unknown | J5: https://caseyinsure.com/ | K5: https://www.ycombinator.com/companies/casey | L5: high
A6: An audit firm that checks a company's financial accounts using AI instead of big teams of junior auditors. | B6: Denki | C6: Y Combinator | D6: YC Fall 2025 | E6: $500K | F6: standard YC deal ($125K for 7% + $375K uncapped SAFE); the startup's own round is not public | G6: San Francisco, CA, USA | H6: USA | I6: unknown | J6: https://denki.ai | K6: https://www.ycombinator.com/companies/denki | L6: high
A7: An insurance company with no human underwriters. AI decides the risk and the price. | B7: Florin | C7: Y Combinator | D7: YC Summer 2026 | E7: $500K | F7: standard YC deal ($125K for 7% + $375K uncapped SAFE); the startup's own round is not public | G7: San Francisco, CA, USA | H7: USA | I7: reported | J7: https://florin.inc | K7: https://www.ycombinator.com/companies/florin | L7: high
A8: A law firm for fast-growing startups where AI drafts the legal work and lawyers review it. | B8: General Legal | C8: Y Combinator | D8: YC Winter 2026 | E8: $500K | F8: standard YC deal ($125K for 7% + $375K uncapped SAFE); the startup's own round is not public | G8: not stated | H8: Other | I8: unknown | J8: https://general.legal | K8: https://www.ycombinator.com/companies/general-legal | L8: high
A9: A firm that runs clinical trials for drug companies and uses AI for the day-to-day trial operations. | B9: Harbor | C9: Y Combinator | D9: YC Spring 2026 | E9: $500K | F9: standard YC deal ($125K for 7% + $375K uncapped SAFE); the startup's own round is not public | G9: San Francisco, CA, USA | H9: USA | I9: unknown | J9: https://runharbor.com/ | K9: https://www.ycombinator.com/companies/runharbor | L9: high
A10: An immigration law firm that uses AI to prepare visa applications faster. | B10: LegalOS | C10: Y Combinator | D10: YC Winter 2026 | E10: $500K | F10: standard YC deal ($125K for 7% + $375K uncapped SAFE); the startup's own round is not public | G10: San Francisco, CA, USA; Remote | H10: USA | I10: unknown | J10: https://www.legalos.ai | K10: https://www.ycombinator.com/companies/legalos | L10: high
A11: An engineering firm that designs data centers and uses AI to do the design work faster. | B11: Marengo | C11: Y Combinator | D11: YC Summer 2026 | E11: $500K | F11: standard YC deal ($125K for 7% + $375K uncapped SAFE); the startup's own round is not public | G11: San Francisco, CA, USA | H11: USA | I11: unknown | J11: https://marengox.com | K11: https://www.ycombinator.com/companies/marengo | L11: high
A12: A freight broker (it matches companies that ship goods with trucks) run by AI. | B12: Peer | C12: Y Combinator | D12: YC Summer 2026 | E12: $500K | F12: standard YC deal ($125K for 7% + $375K uncapped SAFE); the startup's own round is not public | G12: San Francisco, CA, USA | H12: USA | I12: unknown | J12: https://peer-freight.com | K12: https://www.ycombinator.com/companies/peer | L12: high
... A16: An outsourcing firm for banks and finance companies where AI agents operate the computer screens instead of people. | B16: Zomma | C16: Y Combinator | D16: YC Summer 2026 | E16: $500K | F16: standard YC deal ($125K for 7% + $375K uncapped SAFE); the startup's own round is not public | G16: San Francisco, CA, USA | H16: USA | I16: reported | J16: https://zommalabs.com | K16: https://www.ycombinator.com/companies/zomma | L16: high
A17: AI-run home insurance for areas with high climate risk. | B17: Rhino | C17: Antler US | D17: US Spring 2026 Showcase | E17: not disclosed | F17: taken from a third-party list that was not verified against Antler | G17: USA | H17: USA | I17: unknown | K17: https://agentjesse.ai/lists/antler-2026-cohort-companies | L17: low
A18: A tech-enabled insurance broker for small and mid-sized US businesses. | B18: Rosella | C18: Peak XV Surge | D18: Surge 12 (Sep 2026) | E18: $3.7M | F18: Surge invests up to $5M per startup; the figure shown is funding as listed by Inc42, the Surge share is not disclosed | G18: Sydney, Australia | H18: Other | I18: unknown | K18: https://inc42.com/buzz/meet-the-startups-from-peak-xvs-surge-12/ | L18: medium
A19: An AI-built law firm for mergers and commercial real estate deals. | B19: Athena | C19: a16z Speedrun | D19: SR007 (Jul-Oct 2026) | E19: up to $1M | F19: standard Speedrun deal: $500K for 10% now + $500K in the next round | G19: not stated (program runs in San Francisco) | H19: Unknown | I19: unknown | K19: https://www.frontrun.vc/blog/a16z-speedrun-cohort-007-companies/ | L19: medium

Sheet Old-industry AI
A1: Idea in simple words | B1: Startup | C1: Funded by | D1: Batch / cohort | E1: Funding | F1: What the funding number means | G1: Based in | H1: India / USA / Other | I1: Indian founders? | J1: Website | K1: Source | L1: Confidence
A2: Turns the text-message orders that food distributors get into entries in their order system automatically. | B2: Asakana | C2: Y Combinator | D2: YC Fall 2026 | E2: $500K | F2: standard YC deal ($125K for 7% + $375K uncapped SAFE); the startup's own round is not public | G2: San Francisco, CA, USA | H2: USA | I2: unknown | J2: https://www.asakana.co/ | K2: https://www.ycombinator.com/companies/asakana | L2: high
A3: AI employees that take calls, book visits and send technicians for appliance repair companies. | B3: Bernard | C3: Y Combinator | D3: YC Summer 2026 | E3: $500K | F3: standard YC deal ($125K for 7% + $375K uncapped SAFE); the startup's own round is not public | G3: New York City, NY, USA | H3: USA | I3: unknown | J3: https://bernardhq.com/ | K3: https://www.ycombinator.com/companies/bernard | L3: high
A4: AI that reads building drawings and counts the materials, so electrical contractors can price a job quickly. | B4: Bidflow | C4: Y Combinator | D4: YC Winter 2026 | E4: $500K | F4: standard YC deal ($125K for 7% + $375K uncapped SAFE); the startup's own round is not public | G4: New York City, NY, USA | H4: USA | I4: unknown | J4: https://usebidflow.com | K4: https://www.ycombinator.com/companies/bidflow | L4: high
A5: An AI property manager that handles tenants and maintenance for landlords. | B5: Brickwise | C5: Y Combinator | D5: YC Fall 2025 | E5: $500K | F5: standard YC deal ($125K for 7% + $375K uncapped SAFE); the startup's own round is not public | G5: London, England, United Kingdom | H5: Other | I5: unknown | J5: https://www.brickwiseai.com | K5: https://www.ycombinator.com/companies/brickwise | L5: high
A6: AI that answers booking calls and emails for hotel groups. | B6: Codyco | C6: Y Combinator | D6: YC Fall 2025 | E6: $500K | F6: standard YC deal ($125K for 7% + $375K uncapped SAFE); the startup's own round is not public | G6: BY, Germany | H6: Other | I6: unknown | J6: https://www.codyco.ai/en | K6: https://www.ycombinator.com/companies/codyco | L6: high
A7: AI that plans the daily schedule for short-distance trucks. | B7: Dayjob | C7: Y Combinator | D7: YC Spring 2026 | E7: $500K | F7: standard YC deal ($125K for 7% + $375K uncapped SAFE); the startup's own round is not public | G7: London, England, United Kingdom | H7: Other | I7: unknown | J7: https://www.getdayjob.ai | K7: https://www.ycombinator.com/companies/dayjob | L7: high
A8: AI that takes table reservations for restaurants by phone and chat. | B8: Elyra | C8: Y Combinator | D8: YC Spring 2026 | E8: $500K | F8: standard YC deal ($125K for 7% + $375K uncapped SAFE); the startup's own round is not public | G8: Stockholm, Stockholm County, Sweden | H8: Other | I8: unknown | J8: https://www.elyrasystems.com/ | K8: https://www.ycombinator.com/companies/elyra | L8: high
A9: One system with AI that runs a restaurant's kitchen-side admin: ordering stock, tracking inventory, cutting waste. | B9: Marble | C9: Y Combinator | D9: YC Summer 2026 | E9: $500K | F9: standard YC deal ($125K for 7% + $375K uncapped SAFE); the startup's own round is not public | G9: New York City, NY, USA | H9: USA | I9: reported | J9: https://joinmarble.ai/ | K9: https://www.ycombinator.com/companies/joinmarble | L9: high
A10: AI software that runs the paperwork and deals of real-estate brokerages. | B10: RealPact | C10: Y Combinator | D10: YC Summer 2026 | E10: $500K | F10: standard YC deal ($125K for 7% + $375K uncapped SAFE); the startup's own round is not public | G10: San Francisco, CA, USA | H10: USA | I10: reported | J10: https://realpact.ai | K10: https://www.ycombinator.com/companies/realpact | L10: high
A11: AI agents that answer calls and win more jobs for home-service businesses such as plumbers and electricians. | B11: Robby | C11: Y Combinator | D11: YC Winter 2026 | E11: $500K | F11: standard YC deal ($125K for 7% + $375K uncapped SAFE); the startup's own round is not public | G11: New York City, NY, USA | H11: USA | I11: unknown | J11: https://tryrobby.com | K11: https://www.ycombinator.com/companies/robby | L11: high
A12: Uses a restaurant's existing CCTV cameras to watch operations and alert managers in real time. | B12: Shire Intelligence | C12: Y Combinator | D12: YC Fall 2026 | E12: $500K | F12: standard YC deal ($125K for 7% + $375K uncapped SAFE); the startup's own round is not public | G12: Myrtle Beach, SC, USA | H12: USA | I12: unknown | J12: https://shireintelligence.com/ | K12: https://www.ycombinator.com/companies/shire-intelligence | L12: high
A13: AI software that runs daily operations for wholesale distributors. | B13: Whitespace | C13: Y Combinator | D13: YC Summer 2026 | E13: $500K | F13: standard YC deal ($125K for 7% + $375K uncapped SAFE); the startup's own round is not public | G13: San Francisco, CA, USA | H13: USA | I13: unknown | J13: https://whitespacehq.ai/ | K13: https://www.ycombinator.com/companies/whitespace | L13: high
A14: An electric-vehicle fleet platform for ride-hailing drivers. | B14: Milo Drive | C14: Antler India | D14: Portfolio shown on antler.co/india (read 2026-10-13) | E14: up to ₹4 crore (~$425K-$470K) | F14: standard Antler India deal for 11%; amount per startup not disclosed | G14: India | H14: India | I14: yes | K14: https://www.antler.co/india | L14: high
A15: A marketplace that connects kirana stores with nearby distributors for same-day delivery. | B15: Tradeface | C15: Antler India | D15: Portfolio shown on antler.co/india (read 2026-10-13) | E15: up to ₹4 crore (~$425K-$470K) | F15: standard Antler India deal for 11%; amount per startup not disclosed | G15: India | H15: India | I15: yes | K15: https://www.antler.co/india | L15: high
A16: An AI voice agent that answers hotel calls and turns them into bookings. | B16: withQ | C16: Antler US | D16: US Spring 2026 Showcase | E16: not disclosed | F16: taken from a third-party list that was not verified against Antler | G16: USA | H16: USA | I16: unknown | K16: https://agentjesse.ai/lists/antler-2026-cohort-companies | L16: low
A17: An AI employee that does property management work. | B17: Alven | C17: a16z Speedrun | D17: SR007 (Jul-Oct 2026) | E17: up to $1M | F17: standard Speedrun deal: $500K for 10% now + $500K in the next round | G17: not stated (program runs in San Francisco) | H17: Unknown | I17: unknown | K17: https://www.frontrun.vc/blog/a16z-speedrun-cohort-007-companies/ | L17: medium
A18: AI agents for companies that handle hazardous waste. | B18: Colmez | C18: a16z Speedrun | D18: SR007 (Jul-Oct 2026) | E18: up to $1M | F18: standard Speedrun deal: $500K for 10% now + $500K in the next round | G18: not stated (program runs in San Francisco) | H18: Unknown | I18: unknown | K18: https://www.frontrun.vc/blog/a16z-speedrun-cohort-007-companies/ | L18: medium
A19: AI software for the daily work of freight forwarders. | B19: Nimble | C19: a16z Speedrun | D19: SR007 (Jul-Oct 2026) | E19: up to $1M | F19: standard Speedrun deal: $500K for 10% now + $500K in the next round | G19: not stated (program runs in San Francisco) | H19: Unknown | I19: unknown | K19: https://www.frontrun.vc/blog/a16z-speedrun-cohort-007-companies/ | L19: medium
A20: AI that does the pre-construction and land-buying work for home builders. | B20: Parca | C20: a16z Speedrun | D20: SR007 (Jul-Oct 2026) | E20: up to $1M | F20: standard Speedrun deal: $500K for 10% now + $500K in the next round | G20: not stated (program runs in San Francisco) | H20: Unknown | I20: unknown | K20: https://www.frontrun.vc/blog/a16z-speedrun-cohort-007-companies/ | L20: medium
A21: An operating system for freight forwarders. | B21: Rumbo | C21: a16z Speedrun | D21: SR007 (Jul-Oct 2026) | E21: up to $1M | F21: standard Speedrun deal: $500K for 10% now + $500K in the next round | G21: not stated (program runs in San Francisco) | H21: Unknown | I21: unknown | K21: https://www.frontrun.vc/blog/a16z-speedrun-cohort-007-companies/ | L21: medium
A22: AI crews for messy supply-chain operations. | B22: Sotant | C22: a16z Speedrun | D22: SR007 (Jul-Oct 2026) | E22: up to $1M | F22: standard Speedrun deal: $500K for 10% now + $500K in the next round | G22: not stated (program runs in San Francisco) | H22: Unknown | I22: unknown | K22: https://www.frontrun.vc/blog/a16z-speedrun-cohort-007-companies/ | L22: medium

Sheet Finance back-office
A1: Idea in simple words | B1: Startup | C1: Funded by | D1: Batch / cohort | E1: Funding | F1: What the funding number means | G1: Based in | H1: India / USA / Other | I1: Indian founders? | J1: Website | K1: Source | L1: Confidence
A2: AI employees that chase unpaid customer invoices for a company's finance team. | B2: Alder | C2: Y Combinator | D2: YC Fall 2025 | E2: $500K | F2: standard YC deal ($125K for 7% + $375K uncapped SAFE); the startup's own round is not public | G2: San Francisco, CA, USA | H2: USA | I2: unknown | J2: https://meetalder.com/ | K2: https://www.ycombinator.com/companies/alder | L2: high
A3: AI clerks that process the bills a company has to pay. | B3: Clerked | C3: Y Combinator | D3: YC Fall 2025 | E3: $500K | F3: standard YC deal ($125K for 7% + $375K uncapped SAFE); the startup's own round is not public | G3: San Francisco, CA, USA | H3: USA | I3: unknown | J3: https://clerked.ai | K3: https://www.ycombinator.com/companies/clerked | L3: high
A4: AI that processes home-loan applications from start to finish. | B4: Copperlane | C4: Y Combinator | D4: YC Winter 2026 | E4: $500K | F4: standard YC deal ($125K for 7% + $375K uncapped SAFE); the startup's own round is not public | G4: San Francisco, CA, USA | H4: USA | I4: unknown | J4: https://www.copperlane.ai | K4: https://www.ycombinator.com/companies/copperlane | L4: high
A5: AI that prepares tax returns and does bookkeeping for accounting firms. | B5: Cranston AI | C5: Y Combinator | D5: YC Fall 2025 | E5: $500K | F5: standard YC deal ($125K for 7% + $375K uncapped SAFE); the startup's own round is not public | G5: San Francisco, CA, USA | H5: USA | I5: unknown | J5: https://www.cranston.ai | K5: https://www.ycombinator.com/companies/cranston-ai | L5: high
A6: An AI assistant inside Excel for finance analysts who build heavy spreadsheets. | B6: Crunched | C6: Y Combinator | D6: YC Fall 2025 | E6: $500K | F6: standard YC deal ($125K for 7% + $375K uncapped SAFE); the startup's own round is not public | G6: Oslo, Oslo, Norway | H6: Other | I6: unknown | J6: https://usecrunched.com/ | K6: https://www.ycombinator.com/companies/crunched | L6: high
A7: AI that matches payment records for companies that process a very large number of payments. | B7: End Close | C7: Y Combinator | D7: YC Winter 2026 | E7: $500K | F7: standard YC deal ($125K for 7% + $375K uncapped SAFE); the startup's own round is not public | G7: not stated | H7: Other | I7: unknown | J7: https://endclose.com | K7: https://www.ycombinator.com/companies/end-close | L7: high
A8: AI that investigates insurance claims to catch fraud and errors. | B8: Hesper AI | C8: Y Combinator | D8: YC Fall 2026 | E8: $500K | F8: standard YC deal ($125K for 7% + $375K uncapped SAFE); the startup's own round is not public | G8: New York City, NY, USA | H8: USA | I8: unknown | J8: https://gethesperai.com | K8: https://www.ycombinator.com/companies/hesper-ai | L8: high
A9: Reads a borrower's documents (bank statements, bills, e-wallet records) so lenders in emerging markets can approve loans in minutes. | B9: Kita | C9: Y Combinator | D9: YC Winter 2026 | E9: $500K | F9: standard YC deal ($125K for 7% + $375K uncapped SAFE); the startup's own round is not public | G9: San Francisco, CA, USA | H9: USA | I9: unknown | J9: https://www.kita.ai/ | K9: https://www.ycombinator.com/companies/kita | L9: high
A10: An AI platform that credit funds use to analyse and track loans. Reports about $1B of receivables on the platform. | B10: Levocred AI | C10: Y Combinator | D10: YC Summer 2026 | E10: $500K | F10: standard YC deal ($125K for 7% + $375K uncapped SAFE); the startup's own round is not public | G10: San Francisco, CA, USA | H10: USA | I10: yes | J10: https://levocred.com/ | K10: https://www.ycombinator.com/companies/levocred-ai | L10: high
A11: AI that does the checking work of a company's internal audit team. | B11: Oxus | C11: Y Combinator | D11: YC Winter 2026 | E11: $500K | F11: standard YC deal ($125K for 7% + $375K uncapped SAFE); the startup's own round is not public | G11: San Francisco, CA, USA | H11: USA | I11: unknown | J11: https://oxus-ai.com/ | K11: https://www.ycombinator.com/companies/oxus | L11: high
A12: AI that does the back-office work of banks and fintech companies. | B12: Rapidfolio | C12: Y Combinator | D12: YC Summer 2026 | E12: $500K | F12: standard YC deal ($125K for 7% + $375K uncapped SAFE); the startup's own round is not public | G12: San Francisco, CA, USA | H12: USA | I12: reported | J12: https://rapidfolio.com/ | K12: https://www.ycombinator.com/companies/rapidfolio | L12: high
A13: AI junior analysts for private equity firms that buy mid-sized companies. | B13: Zarna | C13: Y Combinator | D13: YC Fall 2025 | E13: $500K | F13: standard YC deal ($125K for 7% + $375K uncapped SAFE); the startup's own round is not public | G13: San Francisco, CA, USA | H13: USA | I13: unknown | J13: https://www.zarnaai.com/ | K13: https://www.ycombinator.com/companies/zarna | L13: high
A14: AI that helps property insurers assess risk. | B14: VelociSure | C14: Antler US | D14: US Spring 2026 Showcase | E14: not disclosed | F14: taken from a third-party list that was not verified against Antler | G14: USA | H14: USA | I14: unknown | K14: https://agentjesse.ai/lists/antler-2026-cohort-companies | L14: low
A15: AI that does due-diligence and financial research for companies and investors. | B15: Binocs | C15: Google for Startups Accelerator: India | D15: 2026 cohort (announced 2026-07-08) | E15: no cash | F15: equity-free 3-month program with mentoring and credits; most companies here already have a product and earlier funding | G15: Bengaluru, India | H15: India | I15: yes | K15: https://inc42.com/buzz/meet-the-20-startups-selected-for-googles-india-startup-accelerator-2026/ | L15: medium
A16: AI agents that do compliance, risk and audit work for financial institutions. | B16: OnFinanceAI | C16: Google for Startups Accelerator: India | D16: 2026 cohort (announced 2026-07-08) | E16: no cash | F16: equity-free 3-month program with mentoring and credits; most companies here already have a product and earlier funding | G16: Bengaluru, India | H16: India | I16: yes | K16: https://inc42.com/buzz/meet-the-20-startups-selected-for-googles-india-startup-accelerator-2026/ | L16: medium
A17: Tools that verify identity and income and automate onboarding checks. | B17: TartanHQ | C17: Google for Startups Accelerator: India | D17: 2026 cohort (announced 2026-07-08) | E17: no cash | F17: equity-free 3-month program with mentoring and credits; most companies here already have a product and earlier funding | G17: Delhi NCR, India | H17: India | I17: yes | K17: https://inc42.com/buzz/meet-the-20-startups-selected-for-googles-india-startup-accelerator-2026/ | L17: medium
A18: Loan processing for commercial real estate that runs by itself. | B18: Corlen | C18: a16z Speedrun | D18: SR007 (Jul-Oct 2026) | E18: up to $1M | F18: standard Speedrun deal: $500K for 10% now + $500K in the next round | G18: not stated (program runs in San Francisco) | H18: Unknown | I18: unknown | K18: https://www.frontrun.vc/blog/a16z-speedrun-cohort-007-companies/ | L18: medium
A19: Turns unpaid customer invoices into cash for service businesses. | B19: Ontem | C19: a16z Speedrun | D19: SR007 (Jul-Oct 2026) | E19: up to $1M | F19: standard Speedrun deal: $500K for 10% now + $500K in the next round | G19: not stated (program runs in San Francisco) | H19: Unknown | I19: unknown | K19: https://www.frontrun.vc/blog/a16z-speedrun-cohort-007-companies/ | L19: medium

Sheet Healthcare AI
A1: Idea in simple words | B1: Startup | C1: Funded by | D1: Batch / cohort | E1: Funding | F1: What the funding number means | G1: Based in | H1: India / USA / Other | I1: Indian founders? | J1: Website | K1: Source | L1: Confidence
A2: Small MRI machines that fit on a truck, so mobile clinics can offer cancer screening for about $250 a scan. | B2: Adialante | C2: Y Combinator | D2: YC Spring 2026 | E2: $500K | F2: standard YC deal ($125K for 7% + $375K uncapped SAFE); the startup's own round is not public | G2: San Francisco, CA, USA | H2: USA | I2: unknown | J2: http://www.adialante.com | K2: https://www.ycombinator.com/companies/adialante | L2: high
A3: Automates how health insurance companies process claims. | B3: Amera | C3: Y Combinator | D3: YC Fall 2025 | E3: $500K | F3: standard YC deal ($125K for 7% + $375K uncapped SAFE); the startup's own round is not public | G3: New York City, NY, USA | H3: USA | I3: unknown | J3: https://amerahealthsolutions.com/ | K3: https://www.ycombinator.com/companies/amera | L3: high
A4: Software that helps nursing homes track and understand their residents' clinical condition. | B4: Ascenix | C4: Y Combinator | D4: YC Fall 2026 | E4: $500K | F4: standard YC deal ($125K for 7% + $375K uncapped SAFE); the startup's own round is not public | G4: Toronto, ON, Canada | H4: Other | I4: unknown | J4: https://www.ascenix.co/ | K4: https://www.ycombinator.com/companies/ascenix | L4: high
A5: AI that fills in insurance pre-approval requests for small medical practices. | B5: ClaimGlide | C5: Y Combinator | D5: YC Winter 2026 | E5: $500K | F5: standard YC deal ($125K for 7% + $375K uncapped SAFE); the startup's own round is not public | G5: Seattle, WA, USA | H5: USA | I5: unknown | J5: https://claimglide.com/ | K5: https://www.ycombinator.com/companies/claimglide | L5: high
A6: AI voice agents that answer every patient call for a clinic and finish the task (booking, refills, billing) in the clinic's records system. | B6: Elite | C6: Y Combinator | D6: YC Summer 2026 | E6: $500K | F6: standard YC deal ($125K for 7% + $375K uncapped SAFE); the startup's own round is not public | G6: New York City, NY, USA | H6: USA | I6: reported | J6: https://elitehq.ai/ | K6: https://www.ycombinator.com/companies/elite | L6: high
A7: AI search over medical records. Reports seven-figure revenue in its first year. | B7: Hubble | C7: Y Combinator | D7: YC Summer 2026 | E7: $500K | F7: standard YC deal ($125K for 7% + $375K uncapped SAFE); the startup's own round is not public | G7: Seattle, WA, USA | H7: USA | I7: reported | J7: https://hubble.ai/ | K7: https://www.ycombinator.com/companies/hubble-ai | L7: high
A8: A cheap 3D ultrasound device that people without specialist training can use. | B8: Lumius | C8: Y Combinator | D8: YC Spring 2026 | E8: $500K | F8: standard YC deal ($125K for 7% + $375K uncapped SAFE); the startup's own round is not public | G8: Durham, NC, USA | H8: USA | I8: unknown | J8: https://www.lumius-imaging.com | K8: https://www.ycombinator.com/companies/lumius | L8: high
A9: AI that phones insurance companies on behalf of hospital billing teams. | B9: LunaBill | C9: Y Combinator | D9: YC Fall 2025 | E9: $500K | F9: standard YC deal ($125K for 7% + $375K uncapped SAFE); the startup's own round is not public | G9: San Francisco, CA, USA | H9: USA | I9: unknown | J9: https://lunabill.com/ | K9: https://www.ycombinator.com/companies/lunabill | L9: high
A10: An AI receptionist and back office for dental clinics. | B10: Patientdesk.ai | C10: Y Combinator | D10: YC Winter 2026 | E10: $500K | F10: standard YC deal ($125K for 7% + $375K uncapped SAFE); the startup's own round is not public | G10: not stated | H10: Other | I10: unknown | J10: https://patientdesk.ai/ | K10: https://www.ycombinator.com/companies/patientdeskai | L10: high
A11: An AI primary-care doctor in a phone app. | B11: Prana | C11: Y Combinator | D11: YC Winter 2026 | E11: $500K | F11: standard YC deal ($125K for 7% + $375K uncapped SAFE); the startup's own round is not public | G11: San Francisco, CA, USA | H11: USA | I11: unknown | J11: https://pranadoc.com | K11: https://www.ycombinator.com/companies/prana-health | L11: high
A12: AI agents that handle calls and routine work for pharmacies. | B12: Remedy | C12: Y Combinator | D12: YC Fall 2025 | E12: $500K | F12: standard YC deal ($125K for 7% + $375K uncapped SAFE); the startup's own round is not public | G12: not stated | H12: Other | I12: unknown | J12: http://www.useremedy.co | K12: https://www.ycombinator.com/companies/remedy | L12: high
... A14: Patient-record software with AI for medical spas and wellness clinics. | B14: Tepali | C14: Y Combinator | D14: YC Winter 2026 | E14: $500K | F14: standard YC deal ($125K for 7% + $375K uncapped SAFE); the startup's own round is not public | G14: New York City, NY, USA | H14: USA | I14: unknown | J14: https://tepali.com | K14: https://www.ycombinator.com/companies/tepali | L14: high
A15: Helps dental practices bring back patients who still need treatment. | B15: Healink | C15: Antler US | D15: US Spring 2026 Showcase | E15: not disclosed | F15: taken from a third-party list that was not verified against Antler | G15: USA | H15: USA | I15: unknown | K15: https://agentjesse.ai/lists/antler-2026-cohort-companies | L15: low
A16: A smartphone-based system that detects eye damage from high blood pressure; used in 18+ Indian villages. | B16: Hypertensight | C16: Emergent Ventures India | D16: 2026 cohorts 16-19 | E16: not disclosed | F16: grant to an individual or project; amounts are not published | G16: India | H16: India | I16: yes | K16: https://marginalrevolution.com/marginalrevolution/2026/09/emergent-ventures-india-19th-cohort.html | L16: medium
A17: Links ordinary eye photos with retinal scans to diagnose eye disease. | B17: Project Lumen AI | C17: Emergent Ventures India | D17: 2026 cohorts 16-19 | E17: not disclosed | F17: grant to an individual or project; amounts are not published | G17: India | H17: India | I17: yes | K17: https://marginalrevolution.com/marginalrevolution/2026/08/emergent-ventures-india-18th-cohort.html | L17: medium
A18: AI tools for radiology: faster MRI scans and disease detection for hospitals. | B18: Aikenist | C18: Google for Startups Accelerator: India | D18: 2026 cohort (announced 2026-07-08) | E18: no cash | F18: equity-free 3-month program with mentoring and credits; most companies here already have a product and earlier funding | G18: Bengaluru, India | H18: India | I18: yes | K18: https://inc42.com/buzz/meet-the-20-startups-selected-for-googles-india-startup-accelerator-2026/ | L18: medium
A19: An app that uses AI to deliver therapy programs for chronic back and joint pain. | B19: FlexifyMe | C19: Google for Startups Accelerator: India | D19: 2026 cohort (announced 2026-07-08) | E19: no cash | F19: equity-free 3-month program with mentoring and credits; most companies here already have a product and earlier funding | G19: Pune, India | H19: India | I19: yes | K19: https://inc42.com/buzz/meet-the-20-startups-selected-for-googles-india-startup-accelerator-2026/ | L19: medium
A20: An AI health assistant that explains symptoms, lab reports and prescriptions. | B20: August AI | C20: Peak XV Surge | D20: Surge 12 (Sep 2026) | E20: $3M | F20: Surge invests up to $5M per startup; the figure shown is funding as listed by Inc42, the Surge share is not disclosed | G20: Bengaluru, India | H20: India | I20: yes | K20: https://inc42.com/buzz/meet-the-startups-from-peak-xvs-surge-12/ | L20: medium
A21: Clinics for children's healthcare: consultations, vaccines and therapies. | B21: Hoola Health | C21: Peak XV Surge | D21: Surge 12 (Sep 2026) | E21: $5M | F21: Surge invests up to $5M per startup; the figure shown is funding as listed by Inc42, the Surge share is not disclosed | G21: Bengaluru, India | H21: India | I21: yes | K21: https://inc42.com/buzz/meet-the-startups-from-peak-xvs-surge-12/ | L21: medium
A22: A low-cost, needle-free test to screen for oral cancer in places with few doctors. | B22: Astraeus Innovus | C22: WTFund (Nikhil Kamath) | D22: Cohort 3, Class of 2026 | E22: ₹20 lakh | F22: grant, no equity taken | G22: India (city not stated) | H22: India | I22: yes | K22: https://odisha.plus/2026/01/nikhil-kamath-wtfund-young-founders-deeptech-healthcare-india/ | L22: medium
A23: Affordable portable robots that help stroke patients do rehab exercises at home. | B23: Bloom Rehab | C23: WTFund (Nikhil Kamath) | D23: Cohort 3, Class of 2026 | E23: ₹20 lakh | F23: grant, no equity taken | G23: India (city not stated) | H23: India | I23: yes | K23: https://odisha.plus/2026/01/nikhil-kamath-wtfund-young-founders-deeptech-healthcare-india/ | L23: medium
A24: An AI device that attaches to a microscope to digitise and analyse pathology slides. | B24: Turocrates AI | C24: WTFund (Nikhil Kamath) | D24: Cohort 3, Class of 2026 | E24: ₹20 lakh | F24: grant, no equity taken | G24: India (city not stated) | H24: India | I24: yes | K24: https://odisha.plus/2026/01/nikhil-kamath-wtfund-young-founders-deeptech-healthcare-india/ | L24: medium
A25: An AI clinician based on functional medicine. | B25: Coherence Health | C25: a16z Speedrun | D25: SR007 (Jul-Oct 2026) | E25: up to $1M | F25: standard Speedrun deal: $500K for 10% now + $500K in the next round | G25: not stated (program runs in San Francisco) | H25: Unknown | I25: unknown | K25: https://www.frontrun.vc/blog/a16z-speedrun-cohort-007-companies/ | L25: medium
